HTTPExc  | No correlation_id | 2025-08-02 17:49:18.658 | backend.api.v2.exceptions.exception_handlers:http_exception_handler:60 - Manual in-code exception was risen.
HTTPExc  | No correlation_id | 2025-08-02 17:49:18.659 | backend.api.v2.exceptions.exception_handlers:http_exception_handler:61 - Status code: 500
HTTPExc  | No correlation_id | 2025-08-02 17:49:18.659 | backend.api.v2.exceptions.exception_handlers:http_exception_handler:62 - Detail: Internal Server Error. Our team is notified.
HTTPExc  | No correlation_id | 2025-08-02 17:49:18.663 | backend.api.v2.exceptions.exception_handlers:log_traceback:28 - <class 'backend.api.v2.exceptions.api.ApiError'> is handled.
HTTPExc  | No correlation_id | 2025-08-02 17:49:18.665 | backend.api.v2.exceptions.exception_handlers:log_traceback:29 - Internal message: Validation failed, Internal code: 1000, HTTP response code: 500, External message: Internal Server Error. Our team is notified., Traceback: Traceback (most recent call last):
  File "/Users/rakuzma/PycharmProjects/LogObsPoC/venv/lib/python3.13/site-packages/starlette/_exception_handler.py", line 42, in wrapped_app
    await app(scope, receive, sender)
  File "/Users/rakuzma/PycharmProjects/LogObsPoC/venv/lib/python3.13/site-packages/starlette/routing.py", line 73, in app
    response = await f(request)
               ^^^^^^^^^^^^^^^^
  File "/Users/rakuzma/PycharmProjects/LogObsPoC/venv/lib/python3.13/site-packages/fastapi/routing.py", line 301, in app
    raw_response = await run_endpoint_function(
                   ^^^^^^^^^^^^^^^^^^^^^^^^^^^^
    ...<3 lines>...
    )
    ^
  File "/Users/rakuzma/PycharmProjects/LogObsPoC/venv/lib/python3.13/site-packages/fastapi/routing.py", line 212, in run_endpoint_function
    return await dependant.call(**values)
           ^^^^^^^^^^^^^^^^^^^^^^^^^^^^^^
  File "/Users/rakuzma/PycharmProjects/LogObsPoC/backend/api/v2/tests/exceptions/test_exception_handlers.py", line 32, in raise_api
    raise api_exceptions.ApiError(
        internal_message="Validation failed",
    )
backend.api.v2.exceptions.api.ApiError

HTTPExc  | No correlation_id | 2025-08-02 17:49:18.666 | backend.api.v2.exceptions.exception_handlers:log_traceback:37 - Response: Internal Server Error. Our team is notified.
HTTPExc  | No correlation_id | 2025-08-02 17:49:18.668 | backend.api.v2.exceptions.exception_handlers:log_traceback:28 - <class 'backend.api.v2.exceptions.auth.AuthError'> is handled.
HTTPExc  | No correlation_id | 2025-08-02 17:49:18.669 | backend.api.v2.exceptions.exception_handlers:log_traceback:29 - Internal message: Validation failed, Internal code: 5000, HTTP response code: 401, External message: You are not authorized., Traceback: Traceback (most recent call last):
  File "/Users/rakuzma/PycharmProjects/LogObsPoC/venv/lib/python3.13/site-packages/starlette/_exception_handler.py", line 42, in wrapped_app
    await app(scope, receive, sender)
  File "/Users/rakuzma/PycharmProjects/LogObsPoC/venv/lib/python3.13/site-packages/starlette/routing.py", line 73, in app
    response = await f(request)
               ^^^^^^^^^^^^^^^^
  File "/Users/rakuzma/PycharmProjects/LogObsPoC/venv/lib/python3.13/site-packages/fastapi/routing.py", line 301, in app
    raw_response = await run_endpoint_function(
                   ^^^^^^^^^^^^^^^^^^^^^^^^^^^^
    ...<3 lines>...
    )
    ^
  File "/Users/rakuzma/PycharmProjects/LogObsPoC/venv/lib/python3.13/site-packages/fastapi/routing.py", line 212, in run_endpoint_function
    return await dependant.call(**values)
           ^^^^^^^^^^^^^^^^^^^^^^^^^^^^^^
  File "/Users/rakuzma/PycharmProjects/LogObsPoC/backend/api/v2/tests/exceptions/test_exception_handlers.py", line 38, in raise_auth
    raise auth_exceptions.AuthError(
        internal_message="Validation failed",
    )
backend.api.v2.exceptions.auth.AuthError

HTTPExc  | No correlation_id | 2025-08-02 17:49:18.671 | backend.api.v2.exceptions.exception_handlers:log_traceback:37 - Response: You are not authorized.
ERROR    | No correlation_id | 2025-08-02 17:49:18.673 | backend.api.v2.exceptions.exception_handlers:log_traceback:28 - <class 'backend.api.v2.exceptions.core.CoreError'> is handled.
ERROR    | No correlation_id | 2025-08-02 17:49:18.673 | backend.api.v2.exceptions.exception_handlers:log_traceback:29 - Internal message: Validation failed, Internal code: 4000, HTTP response code: 500, External message: Internal Server Error. Our team is notified., Traceback: Traceback (most recent call last):
  File "/Users/rakuzma/PycharmProjects/LogObsPoC/venv/lib/python3.13/site-packages/starlette/_exception_handler.py", line 42, in wrapped_app
    await app(scope, receive, sender)
  File "/Users/rakuzma/PycharmProjects/LogObsPoC/venv/lib/python3.13/site-packages/starlette/routing.py", line 73, in app
    response = await f(request)
               ^^^^^^^^^^^^^^^^
  File "/Users/rakuzma/PycharmProjects/LogObsPoC/venv/lib/python3.13/site-packages/fastapi/routing.py", line 301, in app
    raw_response = await run_endpoint_function(
                   ^^^^^^^^^^^^^^^^^^^^^^^^^^^^
    ...<3 lines>...
    )
    ^
  File "/Users/rakuzma/PycharmProjects/LogObsPoC/venv/lib/python3.13/site-packages/fastapi/routing.py", line 212, in run_endpoint_function
    return await dependant.call(**values)
           ^^^^^^^^^^^^^^^^^^^^^^^^^^^^^^
  File "/Users/rakuzma/PycharmProjects/LogObsPoC/backend/api/v2/tests/exceptions/test_exception_handlers.py", line 44, in raise_core
    raise core_exceptions.CoreError(
        internal_message="Validation failed",
    )
backend.api.v2.exceptions.core.CoreError

ERROR    | No correlation_id | 2025-08-02 17:49:18.674 | backend.api.v2.exceptions.exception_handlers:log_traceback:37 - Response: Internal Server Error. Our team is notified.
ERROR    | No correlation_id | 2025-08-02 17:49:18.676 | backend.api.v2.exceptions.exception_handlers:log_traceback:28 - <class 'backend.api.v2.exceptions.cloud.CloudError'> is handled.
ERROR    | No correlation_id | 2025-08-02 17:49:18.677 | backend.api.v2.exceptions.exception_handlers:log_traceback:29 - Internal message: Validation failed, Internal code: 3000, HTTP response code: 500, External message: Internal Server Error. Our team is notified., Traceback: Traceback (most recent call last):
  File "/Users/rakuzma/PycharmProjects/LogObsPoC/venv/lib/python3.13/site-packages/starlette/_exception_handler.py", line 42, in wrapped_app
    await app(scope, receive, sender)
  File "/Users/rakuzma/PycharmProjects/LogObsPoC/venv/lib/python3.13/site-packages/starlette/routing.py", line 73, in app
    response = await f(request)
               ^^^^^^^^^^^^^^^^
  File "/Users/rakuzma/PycharmProjects/LogObsPoC/venv/lib/python3.13/site-packages/fastapi/routing.py", line 301, in app
    raw_response = await run_endpoint_function(
                   ^^^^^^^^^^^^^^^^^^^^^^^^^^^^
    ...<3 lines>...
    )
    ^
  File "/Users/rakuzma/PycharmProjects/LogObsPoC/venv/lib/python3.13/site-packages/fastapi/routing.py", line 212, in run_endpoint_function
    return await dependant.call(**values)
           ^^^^^^^^^^^^^^^^^^^^^^^^^^^^^^
  File "/Users/rakuzma/PycharmProjects/LogObsPoC/backend/api/v2/tests/exceptions/test_exception_handlers.py", line 50, in raise_cloud
    raise cloud_exceptions.CloudError(
        internal_message="Validation failed",
    )
backend.api.v2.exceptions.cloud.CloudError

ERROR    | No correlation_id | 2025-08-02 17:49:18.678 | backend.api.v2.exceptions.exception_handlers:log_traceback:37 - Response: Internal Server Error. Our team is notified.
ERROR    | No correlation_id | 2025-08-02 17:49:18.680 | backend.api.v2.exceptions.exception_handlers:log_traceback:28 - <class 'backend.api.v2.exceptions.db.DbError'> is handled.
ERROR    | No correlation_id | 2025-08-02 17:49:18.680 | backend.api.v2.exceptions.exception_handlers:log_traceback:29 - Internal message: DB timeout, Internal code: 2000, HTTP response code: 500, External message: Internal Server Error. Our team is notified., Traceback: Traceback (most recent call last):
  File "/Users/rakuzma/PycharmProjects/LogObsPoC/venv/lib/python3.13/site-packages/starlette/_exception_handler.py", line 42, in wrapped_app
    await app(scope, receive, sender)
  File "/Users/rakuzma/PycharmProjects/LogObsPoC/venv/lib/python3.13/site-packages/starlette/routing.py", line 73, in app
    response = await f(request)
               ^^^^^^^^^^^^^^^^
  File "/Users/rakuzma/PycharmProjects/LogObsPoC/venv/lib/python3.13/site-packages/fastapi/routing.py", line 301, in app
    raw_response = await run_endpoint_function(
                   ^^^^^^^^^^^^^^^^^^^^^^^^^^^^
    ...<3 lines>...
    )
    ^
  File "/Users/rakuzma/PycharmProjects/LogObsPoC/venv/lib/python3.13/site-packages/fastapi/routing.py", line 212, in run_endpoint_function
    return await dependant.call(**values)
           ^^^^^^^^^^^^^^^^^^^^^^^^^^^^^^
  File "/Users/rakuzma/PycharmProjects/LogObsPoC/backend/api/v2/tests/exceptions/test_exception_handlers.py", line 56, in raise_db
    raise db_exceptions.DbError(
        internal_message="DB timeout",
    )
backend.api.v2.exceptions.db.DbError

ERROR    | No correlation_id | 2025-08-02 17:49:18.681 | backend.api.v2.exceptions.exception_handlers:log_traceback:37 - Response: Internal Server Error. Our team is notified.
CRITICAL | No correlation_id | 2025-08-02 17:49:18.683 | backend.api.v2.exceptions.exception_handlers:log_traceback:28 - <class 'backend.api.v2.exceptions.base.BaseCustomError'> is handled.
CRITICAL | No correlation_id | 2025-08-02 17:49:18.684 | backend.api.v2.exceptions.exception_handlers:log_traceback:29 - Internal message: Invalid custom rule, Internal code: 500, HTTP response code: 500, External message: Internal Server Error. Our team is notified., Traceback: Traceback (most recent call last):
  File "/Users/rakuzma/PycharmProjects/LogObsPoC/venv/lib/python3.13/site-packages/starlette/_exception_handler.py", line 42, in wrapped_app
    await app(scope, receive, sender)
  File "/Users/rakuzma/PycharmProjects/LogObsPoC/venv/lib/python3.13/site-packages/starlette/routing.py", line 73, in app
    response = await f(request)
               ^^^^^^^^^^^^^^^^
  File "/Users/rakuzma/PycharmProjects/LogObsPoC/venv/lib/python3.13/site-packages/fastapi/routing.py", line 301, in app
    raw_response = await run_endpoint_function(
                   ^^^^^^^^^^^^^^^^^^^^^^^^^^^^
    ...<3 lines>...
    )
    ^
  File "/Users/rakuzma/PycharmProjects/LogObsPoC/venv/lib/python3.13/site-packages/fastapi/routing.py", line 212, in run_endpoint_function
    return await dependant.call(**values)
           ^^^^^^^^^^^^^^^^^^^^^^^^^^^^^^
  File "/Users/rakuzma/PycharmProjects/LogObsPoC/backend/api/v2/tests/exceptions/test_exception_handlers.py", line 62, in raise_base
    raise BaseCustomError(
        internal_message="Invalid custom rule",
    )
backend.api.v2.exceptions.base.BaseCustomError

CRITICAL | No correlation_id | 2025-08-02 17:49:18.685 | backend.api.v2.exceptions.exception_handlers:log_traceback:37 - Response: Internal Server Error. Our team is notified.
CRITICAL | No correlation_id | 2025-08-02 17:49:18.687 | backend.api.v2.exceptions.exception_handlers:custom_generic_handler:140 - Generic Exception is handled
ERROR    | No correlation_id | 2025-08-02 17:49:18.690 | backend.api.v2.exceptions.exception_handlers:custom_generic_handler:141 - Unhandled Exception
CRITICAL | No correlation_id | 2025-08-02 17:49:18.692 | backend.api.v2.exceptions.exception_handlers:custom_generic_handler:143 - Response: Internal Server Error. Our team is notified.
