{"text": "Manual in-code exception was risen.\n", "record": {"elapsed": {"repr": "0:00:00.230649", "seconds": 0.230649}, "exception": null, "extra": {"correlation_id": "No correlation_id"}, "file": {"name": "exception_handlers.py", "path": "/Users/rakuzma/PycharmProjects/LogObsPoC/backend/api/v2/exceptions/exception_handlers.py"}, "function": "http_exception_handler", "level": {"icon": "üèÅ", "name": "HTTPExc", "no": 24}, "line": 60, "message": "Manual in-code exception was risen.", "module": "exception_handlers", "name": "backend.api.v2.exceptions.exception_handlers", "process": {"id": 95011, "name": "MainProcess"}, "thread": {"id": 6245920768, "name": "Thread-1 (run_blocking_portal)"}, "time": {"repr": "2025-08-02 17:49:18.658481+02:00", "timestamp": 1754149758.658481}}}
{"text": "Status code: 500\n", "record": {"elapsed": {"repr": "0:00:00.231318", "seconds": 0.231318}, "exception": null, "extra": {"correlation_id": "No correlation_id"}, "file": {"name": "exception_handlers.py", "path": "/Users/rakuzma/PycharmProjects/LogObsPoC/backend/api/v2/exceptions/exception_handlers.py"}, "function": "http_exception_handler", "level": {"icon": "üèÅ", "name": "HTTPExc", "no": 24}, "line": 61, "message": "Status code: 500", "module": "exception_handlers", "name": "backend.api.v2.exceptions.exception_handlers", "process": {"id": 95011, "name": "MainProcess"}, "thread": {"id": 6245920768, "name": "Thread-1 (run_blocking_portal)"}, "time": {"repr": "2025-08-02 17:49:18.659150+02:00", "timestamp": 1754149758.65915}}}
{"text": "Detail: Internal Server Error. Our team is notified.\n", "record": {"elapsed": {"repr": "0:00:00.231698", "seconds": 0.231698}, "exception": null, "extra": {"correlation_id": "No correlation_id"}, "file": {"name": "exception_handlers.py", "path": "/Users/rakuzma/PycharmProjects/LogObsPoC/backend/api/v2/exceptions/exception_handlers.py"}, "function": "http_exception_handler", "level": {"icon": "üèÅ", "name": "HTTPExc", "no": 24}, "line": 62, "message": "Detail: Internal Server Error. Our team is notified.", "module": "exception_handlers", "name": "backend.api.v2.exceptions.exception_handlers", "process": {"id": 95011, "name": "MainProcess"}, "thread": {"id": 6245920768, "name": "Thread-1 (run_blocking_portal)"}, "time": {"repr": "2025-08-02 17:49:18.659530+02:00", "timestamp": 1754149758.65953}}}
{"text": "<class 'backend.api.v2.exceptions.api.ApiError'> is handled.\n", "record": {"elapsed": {"repr": "0:00:00.235493", "seconds": 0.235493}, "exception": null, "extra": {"correlation_id": "No correlation_id"}, "file": {"name": "exception_handlers.py", "path": "/Users/rakuzma/PycharmProjects/LogObsPoC/backend/api/v2/exceptions/exception_handlers.py"}, "function": "log_traceback", "level": {"icon": "üèÅ", "name": "HTTPExc", "no": 24}, "line": 28, "message": "<class 'backend.api.v2.exceptions.api.ApiError'> is handled.", "module": "exception_handlers", "name": "backend.api.v2.exceptions.exception_handlers", "process": {"id": 95011, "name": "MainProcess"}, "thread": {"id": 6245920768, "name": "Thread-2 (run_blocking_portal)"}, "time": {"repr": "2025-08-02 17:49:18.663325+02:00", "timestamp": 1754149758.663325}}}
{"text": "Internal message: Validation failed, Internal code: 1000, HTTP response code: 500, External message: Internal Server Error. Our team is notified., Traceback: Traceback (most recent call last):\n  File \"/Users/rakuzma/PycharmProjects/LogObsPoC/venv/lib/python3.13/site-packages/starlette/_exception_handler.py\", line 42, in wrapped_app\n    await app(scope, receive, sender)\n  File \"/Users/rakuzma/PycharmProjects/LogObsPoC/venv/lib/python3.13/site-packages/starlette/routing.py\", line 73, in app\n    response = await f(request)\n               ^^^^^^^^^^^^^^^^\n  File \"/Users/rakuzma/PycharmProjects/LogObsPoC/venv/lib/python3.13/site-packages/fastapi/routing.py\", line 301, in app\n    raw_response = await run_endpoint_function(\n                   ^^^^^^^^^^^^^^^^^^^^^^^^^^^^\n    ...<3 lines>...\n    )\n    ^\n  File \"/Users/rakuzma/PycharmProjects/LogObsPoC/venv/lib/python3.13/site-packages/fastapi/routing.py\", line 212, in run_endpoint_function\n    return await dependant.call(**values)\n           ^^^^^^^^^^^^^^^^^^^^^^^^^^^^^^\n  File \"/Users/rakuzma/PycharmProjects/LogObsPoC/backend/api/v2/tests/exceptions/test_exception_handlers.py\", line 32, in raise_api\n    raise api_exceptions.ApiError(\n        internal_message=\"Validation failed\",\n    )\nbackend.api.v2.exceptions.api.ApiError\n\nTraceback (most recent call last):\n  File \"/Users/rakuzma/PycharmProjects/LogObsPoC/venv/lib/python3.13/site-packages/starlette/_exception_handler.py\", line 42, in wrapped_app\n    await app(scope, receive, sender)\n  File \"/Users/rakuzma/PycharmProjects/LogObsPoC/venv/lib/python3.13/site-packages/starlette/routing.py\", line 73, in app\n    response = await f(request)\n  File \"/Users/rakuzma/PycharmProjects/LogObsPoC/venv/lib/python3.13/site-packages/fastapi/routing.py\", line 301, in app\n    raw_response = await run_endpoint_function(\n  File \"/Users/rakuzma/PycharmProjects/LogObsPoC/venv/lib/python3.13/site-packages/fastapi/routing.py\", line 212, in run_endpoint_function\n    return await dependant.call(**values)\n  File \"/Users/rakuzma/PycharmProjects/LogObsPoC/backend/api/v2/tests/exceptions/test_exception_handlers.py\", line 32, in raise_api\n    raise api_exceptions.ApiError(\nbackend.api.v2.exceptions.api.ApiError\n", "record": {"elapsed": {"repr": "0:00:00.237577", "seconds": 0.237577}, "exception": {"type": "ApiError", "value": "", "traceback": true}, "extra": {"correlation_id": "No correlation_id"}, "file": {"name": "exception_handlers.py", "path": "/Users/rakuzma/PycharmProjects/LogObsPoC/backend/api/v2/exceptions/exception_handlers.py"}, "function": "log_traceback", "level": {"icon": "üèÅ", "name": "HTTPExc", "no": 24}, "line": 29, "message": "Internal message: Validation failed, Internal code: 1000, HTTP response code: 500, External message: Internal Server Error. Our team is notified., Traceback: Traceback (most recent call last):\n  File \"/Users/rakuzma/PycharmProjects/LogObsPoC/venv/lib/python3.13/site-packages/starlette/_exception_handler.py\", line 42, in wrapped_app\n    await app(scope, receive, sender)\n  File \"/Users/rakuzma/PycharmProjects/LogObsPoC/venv/lib/python3.13/site-packages/starlette/routing.py\", line 73, in app\n    response = await f(request)\n               ^^^^^^^^^^^^^^^^\n  File \"/Users/rakuzma/PycharmProjects/LogObsPoC/venv/lib/python3.13/site-packages/fastapi/routing.py\", line 301, in app\n    raw_response = await run_endpoint_function(\n                   ^^^^^^^^^^^^^^^^^^^^^^^^^^^^\n    ...<3 lines>...\n    )\n    ^\n  File \"/Users/rakuzma/PycharmProjects/LogObsPoC/venv/lib/python3.13/site-packages/fastapi/routing.py\", line 212, in run_endpoint_function\n    return await dependant.call(**values)\n           ^^^^^^^^^^^^^^^^^^^^^^^^^^^^^^\n  File \"/Users/rakuzma/PycharmProjects/LogObsPoC/backend/api/v2/tests/exceptions/test_exception_handlers.py\", line 32, in raise_api\n    raise api_exceptions.ApiError(\n        internal_message=\"Validation failed\",\n    )\nbackend.api.v2.exceptions.api.ApiError\n", "module": "exception_handlers", "name": "backend.api.v2.exceptions.exception_handlers", "process": {"id": 95011, "name": "MainProcess"}, "thread": {"id": 6245920768, "name": "Thread-2 (run_blocking_portal)"}, "time": {"repr": "2025-08-02 17:49:18.665409+02:00", "timestamp": 1754149758.665409}}}
{"text": "Response: Internal Server Error. Our team is notified.\n", "record": {"elapsed": {"repr": "0:00:00.238847", "seconds": 0.238847}, "exception": null, "extra": {"correlation_id": "No correlation_id"}, "file": {"name": "exception_handlers.py", "path": "/Users/rakuzma/PycharmProjects/LogObsPoC/backend/api/v2/exceptions/exception_handlers.py"}, "function": "log_traceback", "level": {"icon": "üèÅ", "name": "HTTPExc", "no": 24}, "line": 37, "message": "Response: Internal Server Error. Our team is notified.", "module": "exception_handlers", "name": "backend.api.v2.exceptions.exception_handlers", "process": {"id": 95011, "name": "MainProcess"}, "thread": {"id": 6245920768, "name": "Thread-2 (run_blocking_portal)"}, "time": {"repr": "2025-08-02 17:49:18.666679+02:00", "timestamp": 1754149758.666679}}}
{"text": "<class 'backend.api.v2.exceptions.auth.AuthError'> is handled.\n", "record": {"elapsed": {"repr": "0:00:00.241106", "seconds": 0.241106}, "exception": null, "extra": {"correlation_id": "No correlation_id"}, "file": {"name": "exception_handlers.py", "path": "/Users/rakuzma/PycharmProjects/LogObsPoC/backend/api/v2/exceptions/exception_handlers.py"}, "function": "log_traceback", "level": {"icon": "üèÅ", "name": "HTTPExc", "no": 24}, "line": 28, "message": "<class 'backend.api.v2.exceptions.auth.AuthError'> is handled.", "module": "exception_handlers", "name": "backend.api.v2.exceptions.exception_handlers", "process": {"id": 95011, "name": "MainProcess"}, "thread": {"id": 6245920768, "name": "Thread-3 (run_blocking_portal)"}, "time": {"repr": "2025-08-02 17:49:18.668938+02:00", "timestamp": 1754149758.668938}}}
{"text": "Internal message: Validation failed, Internal code: 5000, HTTP response code: 401, External message: You are not authorized., Traceback: Traceback (most recent call last):\n  File \"/Users/rakuzma/PycharmProjects/LogObsPoC/venv/lib/python3.13/site-packages/starlette/_exception_handler.py\", line 42, in wrapped_app\n    await app(scope, receive, sender)\n  File \"/Users/rakuzma/PycharmProjects/LogObsPoC/venv/lib/python3.13/site-packages/starlette/routing.py\", line 73, in app\n    response = await f(request)\n               ^^^^^^^^^^^^^^^^\n  File \"/Users/rakuzma/PycharmProjects/LogObsPoC/venv/lib/python3.13/site-packages/fastapi/routing.py\", line 301, in app\n    raw_response = await run_endpoint_function(\n                   ^^^^^^^^^^^^^^^^^^^^^^^^^^^^\n    ...<3 lines>...\n    )\n    ^\n  File \"/Users/rakuzma/PycharmProjects/LogObsPoC/venv/lib/python3.13/site-packages/fastapi/routing.py\", line 212, in run_endpoint_function\n    return await dependant.call(**values)\n           ^^^^^^^^^^^^^^^^^^^^^^^^^^^^^^\n  File \"/Users/rakuzma/PycharmProjects/LogObsPoC/backend/api/v2/tests/exceptions/test_exception_handlers.py\", line 38, in raise_auth\n    raise auth_exceptions.AuthError(\n        internal_message=\"Validation failed\",\n    )\nbackend.api.v2.exceptions.auth.AuthError\n\nTraceback (most recent call last):\n  File \"/Users/rakuzma/PycharmProjects/LogObsPoC/venv/lib/python3.13/site-packages/starlette/_exception_handler.py\", line 42, in wrapped_app\n    await app(scope, receive, sender)\n  File \"/Users/rakuzma/PycharmProjects/LogObsPoC/venv/lib/python3.13/site-packages/starlette/routing.py\", line 73, in app\n    response = await f(request)\n  File \"/Users/rakuzma/PycharmProjects/LogObsPoC/venv/lib/python3.13/site-packages/fastapi/routing.py\", line 301, in app\n    raw_response = await run_endpoint_function(\n  File \"/Users/rakuzma/PycharmProjects/LogObsPoC/venv/lib/python3.13/site-packages/fastapi/routing.py\", line 212, in run_endpoint_function\n    return await dependant.call(**values)\n  File \"/Users/rakuzma/PycharmProjects/LogObsPoC/backend/api/v2/tests/exceptions/test_exception_handlers.py\", line 38, in raise_auth\n    raise auth_exceptions.AuthError(\nbackend.api.v2.exceptions.auth.AuthError\n", "record": {"elapsed": {"repr": "0:00:00.242038", "seconds": 0.242038}, "exception": {"type": "AuthError", "value": "", "traceback": true}, "extra": {"correlation_id": "No correlation_id"}, "file": {"name": "exception_handlers.py", "path": "/Users/rakuzma/PycharmProjects/LogObsPoC/backend/api/v2/exceptions/exception_handlers.py"}, "function": "log_traceback", "level": {"icon": "üèÅ", "name": "HTTPExc", "no": 24}, "line": 29, "message": "Internal message: Validation failed, Internal code: 5000, HTTP response code: 401, External message: You are not authorized., Traceback: Traceback (most recent call last):\n  File \"/Users/rakuzma/PycharmProjects/LogObsPoC/venv/lib/python3.13/site-packages/starlette/_exception_handler.py\", line 42, in wrapped_app\n    await app(scope, receive, sender)\n  File \"/Users/rakuzma/PycharmProjects/LogObsPoC/venv/lib/python3.13/site-packages/starlette/routing.py\", line 73, in app\n    response = await f(request)\n               ^^^^^^^^^^^^^^^^\n  File \"/Users/rakuzma/PycharmProjects/LogObsPoC/venv/lib/python3.13/site-packages/fastapi/routing.py\", line 301, in app\n    raw_response = await run_endpoint_function(\n                   ^^^^^^^^^^^^^^^^^^^^^^^^^^^^\n    ...<3 lines>...\n    )\n    ^\n  File \"/Users/rakuzma/PycharmProjects/LogObsPoC/venv/lib/python3.13/site-packages/fastapi/routing.py\", line 212, in run_endpoint_function\n    return await dependant.call(**values)\n           ^^^^^^^^^^^^^^^^^^^^^^^^^^^^^^\n  File \"/Users/rakuzma/PycharmProjects/LogObsPoC/backend/api/v2/tests/exceptions/test_exception_handlers.py\", line 38, in raise_auth\n    raise auth_exceptions.AuthError(\n        internal_message=\"Validation failed\",\n    )\nbackend.api.v2.exceptions.auth.AuthError\n", "module": "exception_handlers", "name": "backend.api.v2.exceptions.exception_handlers", "process": {"id": 95011, "name": "MainProcess"}, "thread": {"id": 6245920768, "name": "Thread-3 (run_blocking_portal)"}, "time": {"repr": "2025-08-02 17:49:18.669870+02:00", "timestamp": 1754149758.66987}}}
{"text": "Response: You are not authorized.\n", "record": {"elapsed": {"repr": "0:00:00.243255", "seconds": 0.243255}, "exception": null, "extra": {"correlation_id": "No correlation_id"}, "file": {"name": "exception_handlers.py", "path": "/Users/rakuzma/PycharmProjects/LogObsPoC/backend/api/v2/exceptions/exception_handlers.py"}, "function": "log_traceback", "level": {"icon": "üèÅ", "name": "HTTPExc", "no": 24}, "line": 37, "message": "Response: You are not authorized.", "module": "exception_handlers", "name": "backend.api.v2.exceptions.exception_handlers", "process": {"id": 95011, "name": "MainProcess"}, "thread": {"id": 6245920768, "name": "Thread-3 (run_blocking_portal)"}, "time": {"repr": "2025-08-02 17:49:18.671087+02:00", "timestamp": 1754149758.671087}}}
{"text": "<class 'backend.api.v2.exceptions.core.CoreError'> is handled.\n", "record": {"elapsed": {"repr": "0:00:00.245197", "seconds": 0.245197}, "exception": null, "extra": {"correlation_id": "No correlation_id"}, "file": {"name": "exception_handlers.py", "path": "/Users/rakuzma/PycharmProjects/LogObsPoC/backend/api/v2/exceptions/exception_handlers.py"}, "function": "log_traceback", "level": {"icon": "‚ùå", "name": "ERROR", "no": 40}, "line": 28, "message": "<class 'backend.api.v2.exceptions.core.CoreError'> is handled.", "module": "exception_handlers", "name": "backend.api.v2.exceptions.exception_handlers", "process": {"id": 95011, "name": "MainProcess"}, "thread": {"id": 6245920768, "name": "Thread-4 (run_blocking_portal)"}, "time": {"repr": "2025-08-02 17:49:18.673029+02:00", "timestamp": 1754149758.673029}}}
{"text": "Internal message: Validation failed, Internal code: 4000, HTTP response code: 500, External message: Internal Server Error. Our team is notified., Traceback: Traceback (most recent call last):\n  File \"/Users/rakuzma/PycharmProjects/LogObsPoC/venv/lib/python3.13/site-packages/starlette/_exception_handler.py\", line 42, in wrapped_app\n    await app(scope, receive, sender)\n  File \"/Users/rakuzma/PycharmProjects/LogObsPoC/venv/lib/python3.13/site-packages/starlette/routing.py\", line 73, in app\n    response = await f(request)\n               ^^^^^^^^^^^^^^^^\n  File \"/Users/rakuzma/PycharmProjects/LogObsPoC/venv/lib/python3.13/site-packages/fastapi/routing.py\", line 301, in app\n    raw_response = await run_endpoint_function(\n                   ^^^^^^^^^^^^^^^^^^^^^^^^^^^^\n    ...<3 lines>...\n    )\n    ^\n  File \"/Users/rakuzma/PycharmProjects/LogObsPoC/venv/lib/python3.13/site-packages/fastapi/routing.py\", line 212, in run_endpoint_function\n    return await dependant.call(**values)\n           ^^^^^^^^^^^^^^^^^^^^^^^^^^^^^^\n  File \"/Users/rakuzma/PycharmProjects/LogObsPoC/backend/api/v2/tests/exceptions/test_exception_handlers.py\", line 44, in raise_core\n    raise core_exceptions.CoreError(\n        internal_message=\"Validation failed\",\n    )\nbackend.api.v2.exceptions.core.CoreError\n\nTraceback (most recent call last):\n  File \"/Users/rakuzma/PycharmProjects/LogObsPoC/venv/lib/python3.13/site-packages/starlette/_exception_handler.py\", line 42, in wrapped_app\n    await app(scope, receive, sender)\n  File \"/Users/rakuzma/PycharmProjects/LogObsPoC/venv/lib/python3.13/site-packages/starlette/routing.py\", line 73, in app\n    response = await f(request)\n  File \"/Users/rakuzma/PycharmProjects/LogObsPoC/venv/lib/python3.13/site-packages/fastapi/routing.py\", line 301, in app\n    raw_response = await run_endpoint_function(\n  File \"/Users/rakuzma/PycharmProjects/LogObsPoC/venv/lib/python3.13/site-packages/fastapi/routing.py\", line 212, in run_endpoint_function\n    return await dependant.call(**values)\n  File \"/Users/rakuzma/PycharmProjects/LogObsPoC/backend/api/v2/tests/exceptions/test_exception_handlers.py\", line 44, in raise_core\n    raise core_exceptions.CoreError(\nbackend.api.v2.exceptions.core.CoreError\n", "record": {"elapsed": {"repr": "0:00:00.245883", "seconds": 0.245883}, "exception": {"type": "CoreError", "value": "", "traceback": true}, "extra": {"correlation_id": "No correlation_id"}, "file": {"name": "exception_handlers.py", "path": "/Users/rakuzma/PycharmProjects/LogObsPoC/backend/api/v2/exceptions/exception_handlers.py"}, "function": "log_traceback", "level": {"icon": "‚ùå", "name": "ERROR", "no": 40}, "line": 29, "message": "Internal message: Validation failed, Internal code: 4000, HTTP response code: 500, External message: Internal Server Error. Our team is notified., Traceback: Traceback (most recent call last):\n  File \"/Users/rakuzma/PycharmProjects/LogObsPoC/venv/lib/python3.13/site-packages/starlette/_exception_handler.py\", line 42, in wrapped_app\n    await app(scope, receive, sender)\n  File \"/Users/rakuzma/PycharmProjects/LogObsPoC/venv/lib/python3.13/site-packages/starlette/routing.py\", line 73, in app\n    response = await f(request)\n               ^^^^^^^^^^^^^^^^\n  File \"/Users/rakuzma/PycharmProjects/LogObsPoC/venv/lib/python3.13/site-packages/fastapi/routing.py\", line 301, in app\n    raw_response = await run_endpoint_function(\n                   ^^^^^^^^^^^^^^^^^^^^^^^^^^^^\n    ...<3 lines>...\n    )\n    ^\n  File \"/Users/rakuzma/PycharmProjects/LogObsPoC/venv/lib/python3.13/site-packages/fastapi/routing.py\", line 212, in run_endpoint_function\n    return await dependant.call(**values)\n           ^^^^^^^^^^^^^^^^^^^^^^^^^^^^^^\n  File \"/Users/rakuzma/PycharmProjects/LogObsPoC/backend/api/v2/tests/exceptions/test_exception_handlers.py\", line 44, in raise_core\n    raise core_exceptions.CoreError(\n        internal_message=\"Validation failed\",\n    )\nbackend.api.v2.exceptions.core.CoreError\n", "module": "exception_handlers", "name": "backend.api.v2.exceptions.exception_handlers", "process": {"id": 95011, "name": "MainProcess"}, "thread": {"id": 6245920768, "name": "Thread-4 (run_blocking_portal)"}, "time": {"repr": "2025-08-02 17:49:18.673715+02:00", "timestamp": 1754149758.673715}}}
{"text": "Response: Internal Server Error. Our team is notified.\n", "record": {"elapsed": {"repr": "0:00:00.246961", "seconds": 0.246961}, "exception": null, "extra": {"correlation_id": "No correlation_id"}, "file": {"name": "exception_handlers.py", "path": "/Users/rakuzma/PycharmProjects/LogObsPoC/backend/api/v2/exceptions/exception_handlers.py"}, "function": "log_traceback", "level": {"icon": "‚ùå", "name": "ERROR", "no": 40}, "line": 37, "message": "Response: Internal Server Error. Our team is notified.", "module": "exception_handlers", "name": "backend.api.v2.exceptions.exception_handlers", "process": {"id": 95011, "name": "MainProcess"}, "thread": {"id": 6245920768, "name": "Thread-4 (run_blocking_portal)"}, "time": {"repr": "2025-08-02 17:49:18.674793+02:00", "timestamp": 1754149758.674793}}}
{"text": "<class 'backend.api.v2.exceptions.cloud.CloudError'> is handled.\n", "record": {"elapsed": {"repr": "0:00:00.248884", "seconds": 0.248884}, "exception": null, "extra": {"correlation_id": "No correlation_id"}, "file": {"name": "exception_handlers.py", "path": "/Users/rakuzma/PycharmProjects/LogObsPoC/backend/api/v2/exceptions/exception_handlers.py"}, "function": "log_traceback", "level": {"icon": "‚ùå", "name": "ERROR", "no": 40}, "line": 28, "message": "<class 'backend.api.v2.exceptions.cloud.CloudError'> is handled.", "module": "exception_handlers", "name": "backend.api.v2.exceptions.exception_handlers", "process": {"id": 95011, "name": "MainProcess"}, "thread": {"id": 6245920768, "name": "Thread-5 (run_blocking_portal)"}, "time": {"repr": "2025-08-02 17:49:18.676716+02:00", "timestamp": 1754149758.676716}}}
{"text": "Internal message: Validation failed, Internal code: 3000, HTTP response code: 500, External message: Internal Server Error. Our team is notified., Traceback: Traceback (most recent call last):\n  File \"/Users/rakuzma/PycharmProjects/LogObsPoC/venv/lib/python3.13/site-packages/starlette/_exception_handler.py\", line 42, in wrapped_app\n    await app(scope, receive, sender)\n  File \"/Users/rakuzma/PycharmProjects/LogObsPoC/venv/lib/python3.13/site-packages/starlette/routing.py\", line 73, in app\n    response = await f(request)\n               ^^^^^^^^^^^^^^^^\n  File \"/Users/rakuzma/PycharmProjects/LogObsPoC/venv/lib/python3.13/site-packages/fastapi/routing.py\", line 301, in app\n    raw_response = await run_endpoint_function(\n                   ^^^^^^^^^^^^^^^^^^^^^^^^^^^^\n    ...<3 lines>...\n    )\n    ^\n  File \"/Users/rakuzma/PycharmProjects/LogObsPoC/venv/lib/python3.13/site-packages/fastapi/routing.py\", line 212, in run_endpoint_function\n    return await dependant.call(**values)\n           ^^^^^^^^^^^^^^^^^^^^^^^^^^^^^^\n  File \"/Users/rakuzma/PycharmProjects/LogObsPoC/backend/api/v2/tests/exceptions/test_exception_handlers.py\", line 50, in raise_cloud\n    raise cloud_exceptions.CloudError(\n        internal_message=\"Validation failed\",\n    )\nbackend.api.v2.exceptions.cloud.CloudError\n\nTraceback (most recent call last):\n  File \"/Users/rakuzma/PycharmProjects/LogObsPoC/venv/lib/python3.13/site-packages/starlette/_exception_handler.py\", line 42, in wrapped_app\n    await app(scope, receive, sender)\n  File \"/Users/rakuzma/PycharmProjects/LogObsPoC/venv/lib/python3.13/site-packages/starlette/routing.py\", line 73, in app\n    response = await f(request)\n  File \"/Users/rakuzma/PycharmProjects/LogObsPoC/venv/lib/python3.13/site-packages/fastapi/routing.py\", line 301, in app\n    raw_response = await run_endpoint_function(\n  File \"/Users/rakuzma/PycharmProjects/LogObsPoC/venv/lib/python3.13/site-packages/fastapi/routing.py\", line 212, in run_endpoint_function\n    return await dependant.call(**values)\n  File \"/Users/rakuzma/PycharmProjects/LogObsPoC/backend/api/v2/tests/exceptions/test_exception_handlers.py\", line 50, in raise_cloud\n    raise cloud_exceptions.CloudError(\nbackend.api.v2.exceptions.cloud.CloudError\n", "record": {"elapsed": {"repr": "0:00:00.249540", "seconds": 0.24954}, "exception": {"type": "CloudError", "value": "", "traceback": true}, "extra": {"correlation_id": "No correlation_id"}, "file": {"name": "exception_handlers.py", "path": "/Users/rakuzma/PycharmProjects/LogObsPoC/backend/api/v2/exceptions/exception_handlers.py"}, "function": "log_traceback", "level": {"icon": "‚ùå", "name": "ERROR", "no": 40}, "line": 29, "message": "Internal message: Validation failed, Internal code: 3000, HTTP response code: 500, External message: Internal Server Error. Our team is notified., Traceback: Traceback (most recent call last):\n  File \"/Users/rakuzma/PycharmProjects/LogObsPoC/venv/lib/python3.13/site-packages/starlette/_exception_handler.py\", line 42, in wrapped_app\n    await app(scope, receive, sender)\n  File \"/Users/rakuzma/PycharmProjects/LogObsPoC/venv/lib/python3.13/site-packages/starlette/routing.py\", line 73, in app\n    response = await f(request)\n               ^^^^^^^^^^^^^^^^\n  File \"/Users/rakuzma/PycharmProjects/LogObsPoC/venv/lib/python3.13/site-packages/fastapi/routing.py\", line 301, in app\n    raw_response = await run_endpoint_function(\n                   ^^^^^^^^^^^^^^^^^^^^^^^^^^^^\n    ...<3 lines>...\n    )\n    ^\n  File \"/Users/rakuzma/PycharmProjects/LogObsPoC/venv/lib/python3.13/site-packages/fastapi/routing.py\", line 212, in run_endpoint_function\n    return await dependant.call(**values)\n           ^^^^^^^^^^^^^^^^^^^^^^^^^^^^^^\n  File \"/Users/rakuzma/PycharmProjects/LogObsPoC/backend/api/v2/tests/exceptions/test_exception_handlers.py\", line 50, in raise_cloud\n    raise cloud_exceptions.CloudError(\n        internal_message=\"Validation failed\",\n    )\nbackend.api.v2.exceptions.cloud.CloudError\n", "module": "exception_handlers", "name": "backend.api.v2.exceptions.exception_handlers", "process": {"id": 95011, "name": "MainProcess"}, "thread": {"id": 6245920768, "name": "Thread-5 (run_blocking_portal)"}, "time": {"repr": "2025-08-02 17:49:18.677372+02:00", "timestamp": 1754149758.677372}}}
{"text": "Response: Internal Server Error. Our team is notified.\n", "record": {"elapsed": {"repr": "0:00:00.250504", "seconds": 0.250504}, "exception": null, "extra": {"correlation_id": "No correlation_id"}, "file": {"name": "exception_handlers.py", "path": "/Users/rakuzma/PycharmProjects/LogObsPoC/backend/api/v2/exceptions/exception_handlers.py"}, "function": "log_traceback", "level": {"icon": "‚ùå", "name": "ERROR", "no": 40}, "line": 37, "message": "Response: Internal Server Error. Our team is notified.", "module": "exception_handlers", "name": "backend.api.v2.exceptions.exception_handlers", "process": {"id": 95011, "name": "MainProcess"}, "thread": {"id": 6245920768, "name": "Thread-5 (run_blocking_portal)"}, "time": {"repr": "2025-08-02 17:49:18.678336+02:00", "timestamp": 1754149758.678336}}}
{"text": "<class 'backend.api.v2.exceptions.db.DbError'> is handled.\n", "record": {"elapsed": {"repr": "0:00:00.252457", "seconds": 0.252457}, "exception": null, "extra": {"correlation_id": "No correlation_id"}, "file": {"name": "exception_handlers.py", "path": "/Users/rakuzma/PycharmProjects/LogObsPoC/backend/api/v2/exceptions/exception_handlers.py"}, "function": "log_traceback", "level": {"icon": "‚ùå", "name": "ERROR", "no": 40}, "line": 28, "message": "<class 'backend.api.v2.exceptions.db.DbError'> is handled.", "module": "exception_handlers", "name": "backend.api.v2.exceptions.exception_handlers", "process": {"id": 95011, "name": "MainProcess"}, "thread": {"id": 6245920768, "name": "Thread-6 (run_blocking_portal)"}, "time": {"repr": "2025-08-02 17:49:18.680289+02:00", "timestamp": 1754149758.680289}}}
{"text": "Internal message: DB timeout, Internal code: 2000, HTTP response code: 500, External message: Internal Server Error. Our team is notified., Traceback: Traceback (most recent call last):\n  File \"/Users/rakuzma/PycharmProjects/LogObsPoC/venv/lib/python3.13/site-packages/starlette/_exception_handler.py\", line 42, in wrapped_app\n    await app(scope, receive, sender)\n  File \"/Users/rakuzma/PycharmProjects/LogObsPoC/venv/lib/python3.13/site-packages/starlette/routing.py\", line 73, in app\n    response = await f(request)\n               ^^^^^^^^^^^^^^^^\n  File \"/Users/rakuzma/PycharmProjects/LogObsPoC/venv/lib/python3.13/site-packages/fastapi/routing.py\", line 301, in app\n    raw_response = await run_endpoint_function(\n                   ^^^^^^^^^^^^^^^^^^^^^^^^^^^^\n    ...<3 lines>...\n    )\n    ^\n  File \"/Users/rakuzma/PycharmProjects/LogObsPoC/venv/lib/python3.13/site-packages/fastapi/routing.py\", line 212, in run_endpoint_function\n    return await dependant.call(**values)\n           ^^^^^^^^^^^^^^^^^^^^^^^^^^^^^^\n  File \"/Users/rakuzma/PycharmProjects/LogObsPoC/backend/api/v2/tests/exceptions/test_exception_handlers.py\", line 56, in raise_db\n    raise db_exceptions.DbError(\n        internal_message=\"DB timeout\",\n    )\nbackend.api.v2.exceptions.db.DbError\n\nTraceback (most recent call last):\n  File \"/Users/rakuzma/PycharmProjects/LogObsPoC/venv/lib/python3.13/site-packages/starlette/_exception_handler.py\", line 42, in wrapped_app\n    await app(scope, receive, sender)\n  File \"/Users/rakuzma/PycharmProjects/LogObsPoC/venv/lib/python3.13/site-packages/starlette/routing.py\", line 73, in app\n    response = await f(request)\n  File \"/Users/rakuzma/PycharmProjects/LogObsPoC/venv/lib/python3.13/site-packages/fastapi/routing.py\", line 301, in app\n    raw_response = await run_endpoint_function(\n  File \"/Users/rakuzma/PycharmProjects/LogObsPoC/venv/lib/python3.13/site-packages/fastapi/routing.py\", line 212, in run_endpoint_function\n    return await dependant.call(**values)\n  File \"/Users/rakuzma/PycharmProjects/LogObsPoC/backend/api/v2/tests/exceptions/test_exception_handlers.py\", line 56, in raise_db\n    raise db_exceptions.DbError(\nbackend.api.v2.exceptions.db.DbError\n", "record": {"elapsed": {"repr": "0:00:00.253097", "seconds": 0.253097}, "exception": {"type": "DbError", "value": "", "traceback": true}, "extra": {"correlation_id": "No correlation_id"}, "file": {"name": "exception_handlers.py", "path": "/Users/rakuzma/PycharmProjects/LogObsPoC/backend/api/v2/exceptions/exception_handlers.py"}, "function": "log_traceback", "level": {"icon": "‚ùå", "name": "ERROR", "no": 40}, "line": 29, "message": "Internal message: DB timeout, Internal code: 2000, HTTP response code: 500, External message: Internal Server Error. Our team is notified., Traceback: Traceback (most recent call last):\n  File \"/Users/rakuzma/PycharmProjects/LogObsPoC/venv/lib/python3.13/site-packages/starlette/_exception_handler.py\", line 42, in wrapped_app\n    await app(scope, receive, sender)\n  File \"/Users/rakuzma/PycharmProjects/LogObsPoC/venv/lib/python3.13/site-packages/starlette/routing.py\", line 73, in app\n    response = await f(request)\n               ^^^^^^^^^^^^^^^^\n  File \"/Users/rakuzma/PycharmProjects/LogObsPoC/venv/lib/python3.13/site-packages/fastapi/routing.py\", line 301, in app\n    raw_response = await run_endpoint_function(\n                   ^^^^^^^^^^^^^^^^^^^^^^^^^^^^\n    ...<3 lines>...\n    )\n    ^\n  File \"/Users/rakuzma/PycharmProjects/LogObsPoC/venv/lib/python3.13/site-packages/fastapi/routing.py\", line 212, in run_endpoint_function\n    return await dependant.call(**values)\n           ^^^^^^^^^^^^^^^^^^^^^^^^^^^^^^\n  File \"/Users/rakuzma/PycharmProjects/LogObsPoC/backend/api/v2/tests/exceptions/test_exception_handlers.py\", line 56, in raise_db\n    raise db_exceptions.DbError(\n        internal_message=\"DB timeout\",\n    )\nbackend.api.v2.exceptions.db.DbError\n", "module": "exception_handlers", "name": "backend.api.v2.exceptions.exception_handlers", "process": {"id": 95011, "name": "MainProcess"}, "thread": {"id": 6245920768, "name": "Thread-6 (run_blocking_portal)"}, "time": {"repr": "2025-08-02 17:49:18.680929+02:00", "timestamp": 1754149758.680929}}}
{"text": "Response: Internal Server Error. Our team is notified.\n", "record": {"elapsed": {"repr": "0:00:00.254087", "seconds": 0.254087}, "exception": null, "extra": {"correlation_id": "No correlation_id"}, "file": {"name": "exception_handlers.py", "path": "/Users/rakuzma/PycharmProjects/LogObsPoC/backend/api/v2/exceptions/exception_handlers.py"}, "function": "log_traceback", "level": {"icon": "‚ùå", "name": "ERROR", "no": 40}, "line": 37, "message": "Response: Internal Server Error. Our team is notified.", "module": "exception_handlers", "name": "backend.api.v2.exceptions.exception_handlers", "process": {"id": 95011, "name": "MainProcess"}, "thread": {"id": 6245920768, "name": "Thread-6 (run_blocking_portal)"}, "time": {"repr": "2025-08-02 17:49:18.681919+02:00", "timestamp": 1754149758.681919}}}
{"text": "<class 'backend.api.v2.exceptions.base.BaseCustomError'> is handled.\n", "record": {"elapsed": {"repr": "0:00:00.255874", "seconds": 0.255874}, "exception": null, "extra": {"correlation_id": "No correlation_id"}, "file": {"name": "exception_handlers.py", "path": "/Users/rakuzma/PycharmProjects/LogObsPoC/backend/api/v2/exceptions/exception_handlers.py"}, "function": "log_traceback", "level": {"icon": "‚ò†Ô∏è", "name": "CRITICAL", "no": 50}, "line": 28, "message": "<class 'backend.api.v2.exceptions.base.BaseCustomError'> is handled.", "module": "exception_handlers", "name": "backend.api.v2.exceptions.exception_handlers", "process": {"id": 95011, "name": "MainProcess"}, "thread": {"id": 6245920768, "name": "Thread-7 (run_blocking_portal)"}, "time": {"repr": "2025-08-02 17:49:18.683706+02:00", "timestamp": 1754149758.683706}}}
{"text": "Internal message: Invalid custom rule, Internal code: 500, HTTP response code: 500, External message: Internal Server Error. Our team is notified., Traceback: Traceback (most recent call last):\n  File \"/Users/rakuzma/PycharmProjects/LogObsPoC/venv/lib/python3.13/site-packages/starlette/_exception_handler.py\", line 42, in wrapped_app\n    await app(scope, receive, sender)\n  File \"/Users/rakuzma/PycharmProjects/LogObsPoC/venv/lib/python3.13/site-packages/starlette/routing.py\", line 73, in app\n    response = await f(request)\n               ^^^^^^^^^^^^^^^^\n  File \"/Users/rakuzma/PycharmProjects/LogObsPoC/venv/lib/python3.13/site-packages/fastapi/routing.py\", line 301, in app\n    raw_response = await run_endpoint_function(\n                   ^^^^^^^^^^^^^^^^^^^^^^^^^^^^\n    ...<3 lines>...\n    )\n    ^\n  File \"/Users/rakuzma/PycharmProjects/LogObsPoC/venv/lib/python3.13/site-packages/fastapi/routing.py\", line 212, in run_endpoint_function\n    return await dependant.call(**values)\n           ^^^^^^^^^^^^^^^^^^^^^^^^^^^^^^\n  File \"/Users/rakuzma/PycharmProjects/LogObsPoC/backend/api/v2/tests/exceptions/test_exception_handlers.py\", line 62, in raise_base\n    raise BaseCustomError(\n        internal_message=\"Invalid custom rule\",\n    )\nbackend.api.v2.exceptions.base.BaseCustomError\n\nTraceback (most recent call last):\n  File \"/Users/rakuzma/PycharmProjects/LogObsPoC/venv/lib/python3.13/site-packages/starlette/_exception_handler.py\", line 42, in wrapped_app\n    await app(scope, receive, sender)\n  File \"/Users/rakuzma/PycharmProjects/LogObsPoC/venv/lib/python3.13/site-packages/starlette/routing.py\", line 73, in app\n    response = await f(request)\n  File \"/Users/rakuzma/PycharmProjects/LogObsPoC/venv/lib/python3.13/site-packages/fastapi/routing.py\", line 301, in app\n    raw_response = await run_endpoint_function(\n  File \"/Users/rakuzma/PycharmProjects/LogObsPoC/venv/lib/python3.13/site-packages/fastapi/routing.py\", line 212, in run_endpoint_function\n    return await dependant.call(**values)\n  File \"/Users/rakuzma/PycharmProjects/LogObsPoC/backend/api/v2/tests/exceptions/test_exception_handlers.py\", line 62, in raise_base\n    raise BaseCustomError(\nbackend.api.v2.exceptions.base.BaseCustomError\n", "record": {"elapsed": {"repr": "0:00:00.256396", "seconds": 0.256396}, "exception": {"type": "BaseCustomError", "value": "", "traceback": true}, "extra": {"correlation_id": "No correlation_id"}, "file": {"name": "exception_handlers.py", "path": "/Users/rakuzma/PycharmProjects/LogObsPoC/backend/api/v2/exceptions/exception_handlers.py"}, "function": "log_traceback", "level": {"icon": "‚ò†Ô∏è", "name": "CRITICAL", "no": 50}, "line": 29, "message": "Internal message: Invalid custom rule, Internal code: 500, HTTP response code: 500, External message: Internal Server Error. Our team is notified., Traceback: Traceback (most recent call last):\n  File \"/Users/rakuzma/PycharmProjects/LogObsPoC/venv/lib/python3.13/site-packages/starlette/_exception_handler.py\", line 42, in wrapped_app\n    await app(scope, receive, sender)\n  File \"/Users/rakuzma/PycharmProjects/LogObsPoC/venv/lib/python3.13/site-packages/starlette/routing.py\", line 73, in app\n    response = await f(request)\n               ^^^^^^^^^^^^^^^^\n  File \"/Users/rakuzma/PycharmProjects/LogObsPoC/venv/lib/python3.13/site-packages/fastapi/routing.py\", line 301, in app\n    raw_response = await run_endpoint_function(\n                   ^^^^^^^^^^^^^^^^^^^^^^^^^^^^\n    ...<3 lines>...\n    )\n    ^\n  File \"/Users/rakuzma/PycharmProjects/LogObsPoC/venv/lib/python3.13/site-packages/fastapi/routing.py\", line 212, in run_endpoint_function\n    return await dependant.call(**values)\n           ^^^^^^^^^^^^^^^^^^^^^^^^^^^^^^\n  File \"/Users/rakuzma/PycharmProjects/LogObsPoC/backend/api/v2/tests/exceptions/test_exception_handlers.py\", line 62, in raise_base\n    raise BaseCustomError(\n        internal_message=\"Invalid custom rule\",\n    )\nbackend.api.v2.exceptions.base.BaseCustomError\n", "module": "exception_handlers", "name": "backend.api.v2.exceptions.exception_handlers", "process": {"id": 95011, "name": "MainProcess"}, "thread": {"id": 6245920768, "name": "Thread-7 (run_blocking_portal)"}, "time": {"repr": "2025-08-02 17:49:18.684228+02:00", "timestamp": 1754149758.684228}}}
{"text": "Response: Internal Server Error. Our team is notified.\n", "record": {"elapsed": {"repr": "0:00:00.257221", "seconds": 0.257221}, "exception": null, "extra": {"correlation_id": "No correlation_id"}, "file": {"name": "exception_handlers.py", "path": "/Users/rakuzma/PycharmProjects/LogObsPoC/backend/api/v2/exceptions/exception_handlers.py"}, "function": "log_traceback", "level": {"icon": "‚ò†Ô∏è", "name": "CRITICAL", "no": 50}, "line": 37, "message": "Response: Internal Server Error. Our team is notified.", "module": "exception_handlers", "name": "backend.api.v2.exceptions.exception_handlers", "process": {"id": 95011, "name": "MainProcess"}, "thread": {"id": 6245920768, "name": "Thread-7 (run_blocking_portal)"}, "time": {"repr": "2025-08-02 17:49:18.685053+02:00", "timestamp": 1754149758.685053}}}
{"text": "Generic Exception is handled\nTraceback (most recent call last):\n  File \"/Users/rakuzma/PycharmProjects/LogObsPoC/venv/lib/python3.13/site-packages/starlette/middleware/errors.py\", line 165, in __call__\n    await self.app(scope, receive, _send)\n  File \"/Users/rakuzma/PycharmProjects/LogObsPoC/venv/lib/python3.13/site-packages/starlette/middleware/exceptions.py\", line 62, in __call__\n    await wrap_app_handling_exceptions(self.app, conn)(scope, receive, send)\n  File \"/Users/rakuzma/PycharmProjects/LogObsPoC/venv/lib/python3.13/site-packages/starlette/_exception_handler.py\", line 53, in wrapped_app\n    raise exc\n  File \"/Users/rakuzma/PycharmProjects/LogObsPoC/venv/lib/python3.13/site-packages/starlette/_exception_handler.py\", line 42, in wrapped_app\n    await app(scope, receive, sender)\n  File \"/Users/rakuzma/PycharmProjects/LogObsPoC/venv/lib/python3.13/site-packages/starlette/routing.py\", line 714, in __call__\n    await self.middleware_stack(scope, receive, send)\n  File \"/Users/rakuzma/PycharmProjects/LogObsPoC/venv/lib/python3.13/site-packages/starlette/routing.py\", line 734, in app\n    await route.handle(scope, receive, send)\n  File \"/Users/rakuzma/PycharmProjects/LogObsPoC/venv/lib/python3.13/site-packages/starlette/routing.py\", line 288, in handle\n    await self.app(scope, receive, send)\n  File \"/Users/rakuzma/PycharmProjects/LogObsPoC/venv/lib/python3.13/site-packages/starlette/routing.py\", line 76, in app\n    await wrap_app_handling_exceptions(app, request)(scope, receive, send)\n  File \"/Users/rakuzma/PycharmProjects/LogObsPoC/venv/lib/python3.13/site-packages/starlette/_exception_handler.py\", line 53, in wrapped_app\n    raise exc\n  File \"/Users/rakuzma/PycharmProjects/LogObsPoC/venv/lib/python3.13/site-packages/starlette/_exception_handler.py\", line 42, in wrapped_app\n    await app(scope, receive, sender)\n  File \"/Users/rakuzma/PycharmProjects/LogObsPoC/venv/lib/python3.13/site-packages/starlette/routing.py\", line 73, in app\n    response = await f(request)\n  File \"/Users/rakuzma/PycharmProjects/LogObsPoC/venv/lib/python3.13/site-packages/fastapi/routing.py\", line 301, in app\n    raw_response = await run_endpoint_function(\n  File \"/Users/rakuzma/PycharmProjects/LogObsPoC/venv/lib/python3.13/site-packages/fastapi/routing.py\", line 212, in run_endpoint_function\n    return await dependant.call(**values)\n  File \"/Users/rakuzma/PycharmProjects/LogObsPoC/backend/api/v2/tests/exceptions/test_exception_handlers.py\", line 68, in raise_generic\n    raise RuntimeError(\"Unexpected error\")\nRuntimeError: Unexpected error\n", "record": {"elapsed": {"repr": "0:00:00.259796", "seconds": 0.259796}, "exception": {"type": "RuntimeError", "value": "Unexpected error", "traceback": true}, "extra": {"correlation_id": "No correlation_id"}, "file": {"name": "exception_handlers.py", "path": "/Users/rakuzma/PycharmProjects/LogObsPoC/backend/api/v2/exceptions/exception_handlers.py"}, "function": "custom_generic_handler", "level": {"icon": "‚ò†Ô∏è", "name": "CRITICAL", "no": 50}, "line": 140, "message": "Generic Exception is handled", "module": "exception_handlers", "name": "backend.api.v2.exceptions.exception_handlers", "process": {"id": 95011, "name": "MainProcess"}, "thread": {"id": 6245920768, "name": "Thread-8 (run_blocking_portal)"}, "time": {"repr": "2025-08-02 17:49:18.687628+02:00", "timestamp": 1754149758.687628}}}
{"text": "Unhandled Exception\nTraceback (most recent call last):\n  File \"/Users/rakuzma/PycharmProjects/LogObsPoC/venv/lib/python3.13/site-packages/starlette/middleware/errors.py\", line 165, in __call__\n    await self.app(scope, receive, _send)\n  File \"/Users/rakuzma/PycharmProjects/LogObsPoC/venv/lib/python3.13/site-packages/starlette/middleware/exceptions.py\", line 62, in __call__\n    await wrap_app_handling_exceptions(self.app, conn)(scope, receive, send)\n  File \"/Users/rakuzma/PycharmProjects/LogObsPoC/venv/lib/python3.13/site-packages/starlette/_exception_handler.py\", line 53, in wrapped_app\n    raise exc\n  File \"/Users/rakuzma/PycharmProjects/LogObsPoC/venv/lib/python3.13/site-packages/starlette/_exception_handler.py\", line 42, in wrapped_app\n    await app(scope, receive, sender)\n  File \"/Users/rakuzma/PycharmProjects/LogObsPoC/venv/lib/python3.13/site-packages/starlette/routing.py\", line 714, in __call__\n    await self.middleware_stack(scope, receive, send)\n  File \"/Users/rakuzma/PycharmProjects/LogObsPoC/venv/lib/python3.13/site-packages/starlette/routing.py\", line 734, in app\n    await route.handle(scope, receive, send)\n  File \"/Users/rakuzma/PycharmProjects/LogObsPoC/venv/lib/python3.13/site-packages/starlette/routing.py\", line 288, in handle\n    await self.app(scope, receive, send)\n  File \"/Users/rakuzma/PycharmProjects/LogObsPoC/venv/lib/python3.13/site-packages/starlette/routing.py\", line 76, in app\n    await wrap_app_handling_exceptions(app, request)(scope, receive, send)\n  File \"/Users/rakuzma/PycharmProjects/LogObsPoC/venv/lib/python3.13/site-packages/starlette/_exception_handler.py\", line 53, in wrapped_app\n    raise exc\n  File \"/Users/rakuzma/PycharmProjects/LogObsPoC/venv/lib/python3.13/site-packages/starlette/_exception_handler.py\", line 42, in wrapped_app\n    await app(scope, receive, sender)\n  File \"/Users/rakuzma/PycharmProjects/LogObsPoC/venv/lib/python3.13/site-packages/starlette/routing.py\", line 73, in app\n    response = await f(request)\n  File \"/Users/rakuzma/PycharmProjects/LogObsPoC/venv/lib/python3.13/site-packages/fastapi/routing.py\", line 301, in app\n    raw_response = await run_endpoint_function(\n  File \"/Users/rakuzma/PycharmProjects/LogObsPoC/venv/lib/python3.13/site-packages/fastapi/routing.py\", line 212, in run_endpoint_function\n    return await dependant.call(**values)\n  File \"/Users/rakuzma/PycharmProjects/LogObsPoC/backend/api/v2/tests/exceptions/test_exception_handlers.py\", line 68, in raise_generic\n    raise RuntimeError(\"Unexpected error\")\nRuntimeError: Unexpected error\n", "record": {"elapsed": {"repr": "0:00:00.262762", "seconds": 0.262762}, "exception": {"type": "RuntimeError", "value": "Unexpected error", "traceback": true}, "extra": {"correlation_id": "No correlation_id"}, "file": {"name": "exception_handlers.py", "path": "/Users/rakuzma/PycharmProjects/LogObsPoC/backend/api/v2/exceptions/exception_handlers.py"}, "function": "custom_generic_handler", "level": {"icon": "‚ùå", "name": "ERROR", "no": 40}, "line": 141, "message": "Unhandled Exception", "module": "exception_handlers", "name": "backend.api.v2.exceptions.exception_handlers", "process": {"id": 95011, "name": "MainProcess"}, "thread": {"id": 6245920768, "name": "Thread-8 (run_blocking_portal)"}, "time": {"repr": "2025-08-02 17:49:18.690594+02:00", "timestamp": 1754149758.690594}}}
{"text": "Response: Internal Server Error. Our team is notified.\n", "record": {"elapsed": {"repr": "0:00:00.264644", "seconds": 0.264644}, "exception": null, "extra": {"correlation_id": "No correlation_id"}, "file": {"name": "exception_handlers.py", "path": "/Users/rakuzma/PycharmProjects/LogObsPoC/backend/api/v2/exceptions/exception_handlers.py"}, "function": "custom_generic_handler", "level": {"icon": "‚ò†Ô∏è", "name": "CRITICAL", "no": 50}, "line": 143, "message": "Response: Internal Server Error. Our team is notified.", "module": "exception_handlers", "name": "backend.api.v2.exceptions.exception_handlers", "process": {"id": 95011, "name": "MainProcess"}, "thread": {"id": 6245920768, "name": "Thread-8 (run_blocking_portal)"}, "time": {"repr": "2025-08-02 17:49:18.692476+02:00", "timestamp": 1754149758.692476}}}
